{"text": "2024-02-04 18:17:46 | INFO    | __main__:stash:131 | run - {'image': '20231121', 'version': '0.10.1.post2', 'role': 'EpicPlayer', 'headless': True}\n", "record": {"elapsed": {"repr": "0:00:02.073379", "seconds": 2.073379}, "exception": null, "extra": {"image": "20231121", "version": "0.10.1.post2", "role": "EpicPlayer", "headless": true}, "file": {"name": "claim.py", "path": "/home/runner/work/epic-awesome-gamer/epic-awesome-gamer/epic/src/claim.py"}, "function": "stash", "level": {"icon": "ℹ️", "name": "INFO", "no": 20}, "line": 131, "message": "run", "module": "claim", "name": "__main__", "process": {"id": 3513, "name": "MainProcess"}, "thread": {"id": 140096982690688, "name": "MainThread"}, "time": {"repr": "2024-02-04 18:17:46.818294+08:00", "timestamp": 1707041866.818294}}}
{"text": "2024-02-04 18:17:56 | INFO    | __main__:claim_epic_games:97 | Try to flush cookie - {'task': 'claim_epic_games'}\n", "record": {"elapsed": {"repr": "0:00:11.841157", "seconds": 11.841157}, "exception": null, "extra": {"task": "claim_epic_games"}, "file": {"name": "claim.py", "path": "/home/runner/work/epic-awesome-gamer/epic-awesome-gamer/epic/src/claim.py"}, "function": "claim_epic_games", "level": {"icon": "ℹ️", "name": "INFO", "no": 20}, "line": 97, "message": "Try to flush cookie", "module": "claim", "name": "__main__", "process": {"id": 3513, "name": "MainProcess"}, "thread": {"id": 140096982690688, "name": "MainThread"}, "time": {"repr": "2024-02-04 18:17:56.586072+08:00", "timestamp": 1707041876.586072}}}
{"text": "2024-02-04 18:17:58 | SUCCESS    | epic_games.agent:_login:253 | login - {'result': 'Successfully refreshed tokens'}\n", "record": {"elapsed": {"repr": "0:00:13.997736", "seconds": 13.997736}, "exception": null, "extra": {"result": "Successfully refreshed tokens"}, "file": {"name": "agent.py", "path": "/home/runner/work/epic-awesome-gamer/epic-awesome-gamer/epic/src/epic_games/agent.py"}, "function": "_login", "level": {"icon": "✅", "name": "SUCCESS", "no": 25}, "line": 253, "message": "login", "module": "agent", "name": "epic_games.agent", "process": {"id": 3513, "name": "MainProcess"}, "thread": {"id": 140096982690688, "name": "MainThread"}, "time": {"repr": "2024-02-04 18:17:58.742651+08:00", "timestamp": 1707041878.742651}}}
{"text": "2024-02-04 18:18:29 | ERROR    | __main__:run:158 | An error has been caught in function 'run', process 'MainProcess' (3513), thread 'MainThread' (140096982690688): - {}\nTraceback (most recent call last):\n  File \"/home/runner/work/epic-awesome-gamer/epic-awesome-gamer/epic/src/claim.py\", line 162, in <module>\n    asyncio.run(run())\n  File \"/opt/hostedtoolcache/Python/3.10.13/x64/lib/python3.10/asyncio/runners.py\", line 44, in run\n    return loop.run_until_complete(main)\n  File \"/opt/hostedtoolcache/Python/3.10.13/x64/lib/python3.10/asyncio/base_events.py\", line 636, in run_until_complete\n    self.run_forever()\n  File \"/opt/hostedtoolcache/Python/3.10.13/x64/lib/python3.10/asyncio/base_events.py\", line 603, in run_forever\n    self._run_once()\n  File \"/opt/hostedtoolcache/Python/3.10.13/x64/lib/python3.10/asyncio/base_events.py\", line 1909, in _run_once\n    handle._run()\n  File \"/opt/hostedtoolcache/Python/3.10.13/x64/lib/python3.10/asyncio/events.py\", line 80, in _run\n    self._context.run(self._callback, *self._args)\n> File \"/home/runner/work/epic-awesome-gamer/epic-awesome-gamer/epic/src/claim.py\", line 158, in run\n    await agent.stash()\n  File \"/home/runner/work/epic-awesome-gamer/epic-awesome-gamer/epic/src/claim.py\", line 151, in stash\n    await self.claim_epic_games(context)\n  File \"/home/runner/work/epic-awesome-gamer/epic-awesome-gamer/epic/src/claim.py\", line 99, in claim_epic_games\n    cookies = await epic.flush_token(context)\n  File \"/home/runner/work/epic-awesome-gamer/epic-awesome-gamer/epic/src/epic_games/agent.py\", line 273, in flush_token\n    await page.goto(\"https://www.epicgames.com/account/personal\", wait_until=\"networkidle\")\n  File \"/opt/hostedtoolcache/Python/3.10.13/x64/lib/python3.10/site-packages/playwright/async_api/_generated.py\", line 9275, in goto\n    await self._impl_obj.goto(\n  File \"/opt/hostedtoolcache/Python/3.10.13/x64/lib/python3.10/site-packages/playwright/_impl/_page.py\", line 484, in goto\n    return await self._main_frame.goto(**locals_to_params(locals()))\n  File \"/opt/hostedtoolcache/Python/3.10.13/x64/lib/python3.10/site-packages/playwright/_impl/_frame.py\", line 149, in goto\n    await self._channel.send(\"goto\", locals_to_params(locals()))\n  File \"/opt/hostedtoolcache/Python/3.10.13/x64/lib/python3.10/site-packages/playwright/_impl/_connection.py\", line 63, in send\n    return await self._connection.wrap_api_call(\n  File \"/opt/hostedtoolcache/Python/3.10.13/x64/lib/python3.10/site-packages/playwright/_impl/_connection.py\", line 495, in wrap_api_call\n    return await cb()\n  File \"/opt/hostedtoolcache/Python/3.10.13/x64/lib/python3.10/site-packages/playwright/_impl/_connection.py\", line 101, in inner_send\n    result = next(iter(done)).result()\nplaywright._impl._errors.TimeoutError: Timeout 30000ms exceeded.\n", "record": {"elapsed": {"repr": "0:00:45.230053", "seconds": 45.230053}, "exception": {"type": "TimeoutError", "value": "Timeout 30000ms exceeded.", "traceback": true}, "extra": {}, "file": {"name": "claim.py", "path": "/home/runner/work/epic-awesome-gamer/epic-awesome-gamer/epic/src/claim.py"}, "function": "run", "level": {"icon": "❌", "name": "ERROR", "no": 40}, "line": 158, "message": "An error has been caught in function 'run', process 'MainProcess' (3513), thread 'MainThread' (140096982690688):", "module": "claim", "name": "__main__", "process": {"id": 3513, "name": "MainProcess"}, "thread": {"id": 140096982690688, "name": "MainThread"}, "time": {"repr": "2024-02-04 18:18:29.974968+08:00", "timestamp": 1707041909.974968}}}
